INFO 2020-04-24 17:25:02,436 autoreload 598 Watching for file changes with StatReloader
INFO 2020-04-24 17:26:44,128 autoreload 598 Watching for file changes with StatReloader
INFO 2020-04-24 17:26:55,455 autoreload 222 /usr/src/app/src/settings.py changed, reloading.
INFO 2020-04-24 17:26:56,444 autoreload 598 Watching for file changes with StatReloader
INFO 2020-04-24 17:28:39,429 autoreload 222 /usr/src/app/apps/verifications/views.py changed, reloading.
INFO 2020-04-24 17:28:40,428 autoreload 598 Watching for file changes with StatReloader
INFO 2020-04-24 17:29:04,454 autoreload 222 /usr/src/app/celery_tasks/sms/tasks.py changed, reloading.
INFO 2020-04-24 17:29:05,468 autoreload 598 Watching for file changes with StatReloader
INFO 2020-04-24 17:29:39,422 autoreload 222 /usr/src/app/src/settings.py changed, reloading.
INFO 2020-04-24 17:29:40,415 autoreload 598 Watching for file changes with StatReloader
INFO 2020-04-24 17:30:11,909 autoreload 222 /usr/src/app/libs/yuntongxun/ccp_sms.py changed, reloading.
INFO 2020-04-24 17:30:12,886 autoreload 598 Watching for file changes with StatReloader
INFO 2020-04-24 17:30:28,553 autoreload 222 /usr/src/app/celery_tasks/sms/tasks.py changed, reloading.
INFO 2020-04-24 17:30:29,659 autoreload 598 Watching for file changes with StatReloader
INFO 2020-04-24 17:30:36,369 basehttp 157 "GET /image_codes/1 HTTP/1.1" 301 0
INFO 2020-04-24 17:30:36,484 basehttp 157 "GET /image_codes/1/ HTTP/1.1" 200 2826
INFO 2020-04-24 17:31:08,523 basehttp 157 "GET /sms_code/15850530699?image_code=dvjf&uuid=1 HTTP/1.1" 301 0
INFO 2020-04-24 17:31:08,827 basehttp 157 "GET /sms_code/15850530699/?image_code=dvjf&uuid=1 HTTP/1.1" 200 29
INFO 2020-04-24 17:33:41,631 basehttp 157 "GET /image_codes/1 HTTP/1.1" 301 0
INFO 2020-04-24 17:33:41,688 basehttp 157 "GET /image_codes/1/ HTTP/1.1" 200 3607
INFO 2020-04-24 17:33:48,535 basehttp 157 "GET /sms_code/15850530699?image_code=um09&uuid=1 HTTP/1.1" 301 0
WARNING 2020-04-24 17:33:48,584 log 222 Bad Request: /sms_code/15850530699/
WARNING 2020-04-24 17:33:48,585 basehttp 157 "GET /sms_code/15850530699/?image_code=um09&uuid=1 HTTP/1.1" 400 48
INFO 2020-04-24 17:33:56,808 basehttp 157 "GET /sms_code/15850530699?image_code=umo9&uuid=1 HTTP/1.1" 301 0
INFO 2020-04-24 17:33:56,857 basehttp 157 "GET /sms_code/15850530699/?image_code=umo9&uuid=1 HTTP/1.1" 200 72
INFO 2020-04-24 17:33:59,880 basehttp 157 "GET /image_codes/1 HTTP/1.1" 301 0
INFO 2020-04-24 17:34:00,004 basehttp 157 "GET /image_codes/1/ HTTP/1.1" 200 3214
INFO 2020-04-24 17:34:05,472 basehttp 157 "GET /sms_code/15850530699?image_code=pcdl&uuid=1 HTTP/1.1" 301 0
INFO 2020-04-24 17:34:05,528 basehttp 157 "GET /sms_code/15850530699/?image_code=pcdl&uuid=1 HTTP/1.1" 200 29
INFO 2020-04-24 18:24:15,112 basehttp 157 "GET /admin/ HTTP/1.1" 200 2582
INFO 2020-04-24 18:24:15,167 basehttp 157 "GET /static/admin/css/base.css HTTP/1.1" 200 16378
INFO 2020-04-24 18:24:15,177 basehttp 157 "GET /static/admin/css/responsive.css HTTP/1.1" 200 18052
INFO 2020-04-24 18:24:15,189 basehttp 157 "GET /static/admin/css/dashboard.css HTTP/1.1" 200 412
INFO 2020-04-24 18:24:15,201 basehttp 157 "GET /static/admin/css/fonts.css HTTP/1.1" 200 423
INFO 2020-04-24 18:24:15,477 basehttp 157 "GET /static/admin/img/icon-changelink.svg HTTP/1.1" 200 380
INFO 2020-04-24 18:24:15,478 basehttp 157 "GET /static/admin/img/icon-addlink.svg HTTP/1.1" 200 331
INFO 2020-04-24 18:24:15,564 basehttp 157 "GET /static/admin/fonts/Roboto-Bold-webfont.woff HTTP/1.1" 200 86184
INFO 2020-04-24 18:24:15,569 basehttp 157 "GET /static/admin/fonts/Roboto-Regular-webfont.woff HTTP/1.1" 200 85876
INFO 2020-04-24 18:24:15,578 basehttp 157 "GET /static/admin/fonts/Roboto-Light-webfont.woff HTTP/1.1" 200 85692
INFO 2020-04-24 18:25:29,625 tasks 24 发送短信验证码[正常][mobile: 15850530699]
WARNING 2020-04-24 18:25:29,655 tasks 26 发送短信验证码[失败][mobile: 15850530699]
INFO 2020-04-24 18:27:46,924 autoreload 222 /usr/src/app/apps/users/views.py changed, reloading.
INFO 2020-04-24 18:27:47,913 autoreload 598 Watching for file changes with StatReloader
INFO 2020-04-24 18:28:18,133 autoreload 222 /usr/src/app/apps/users/views.py changed, reloading.
INFO 2020-04-24 18:28:19,060 autoreload 598 Watching for file changes with StatReloader
INFO 2020-04-24 18:29:17,883 autoreload 222 /usr/src/app/apps/users/views.py changed, reloading.
INFO 2020-04-24 18:29:18,998 autoreload 598 Watching for file changes with StatReloader
INFO 2020-04-24 18:29:40,733 autoreload 222 /usr/src/app/apps/users/views.py changed, reloading.
INFO 2020-04-24 18:29:41,740 autoreload 598 Watching for file changes with StatReloader
INFO 2020-04-24 18:34:48,333 autoreload 222 /usr/src/app/apps/users/urls.py changed, reloading.
INFO 2020-04-24 18:34:49,298 autoreload 598 Watching for file changes with StatReloader
INFO 2020-04-24 19:38:10,119 autoreload 222 /usr/src/app/src/settings.py changed, reloading.
INFO 2020-04-24 19:38:11,149 autoreload 598 Watching for file changes with StatReloader
INFO 2020-04-24 19:44:21,942 autoreload 222 /usr/src/app/apps/users/views.py changed, reloading.
INFO 2020-04-24 19:44:23,062 autoreload 598 Watching for file changes with StatReloader
INFO 2020-04-24 19:46:07,418 autoreload 222 /usr/src/app/apps/users/views.py changed, reloading.
INFO 2020-04-24 19:46:08,437 autoreload 598 Watching for file changes with StatReloader
INFO 2020-04-24 19:46:26,942 autoreload 222 /usr/src/app/apps/users/views.py changed, reloading.
INFO 2020-04-24 19:46:28,068 autoreload 598 Watching for file changes with StatReloader
INFO 2020-04-24 19:47:13,240 autoreload 222 /usr/src/app/apps/users/views.py changed, reloading.
INFO 2020-04-24 19:47:14,175 autoreload 598 Watching for file changes with StatReloader
INFO 2020-04-24 19:59:19,497 autoreload 222 /usr/src/app/src/settings.py changed, reloading.
INFO 2020-04-24 19:59:20,715 autoreload 598 Watching for file changes with StatReloader
INFO 2020-04-24 20:00:02,758 autoreload 222 /usr/src/app/apps/users/urls.py changed, reloading.
INFO 2020-04-24 20:00:04,080 autoreload 598 Watching for file changes with StatReloader
INFO 2020-04-24 20:00:19,966 autoreload 222 /usr/src/app/apps/users/urls.py changed, reloading.
INFO 2020-04-24 20:00:21,161 autoreload 598 Watching for file changes with StatReloader
INFO 2020-04-24 20:00:54,605 autoreload 222 /usr/src/app/apps/users/urls.py changed, reloading.
INFO 2020-04-24 20:00:55,830 autoreload 598 Watching for file changes with StatReloader
INFO 2020-04-24 22:30:24,781 autoreload 222 /usr/src/app/apps/users/urls.py changed, reloading.
INFO 2020-04-24 22:30:26,566 autoreload 598 Watching for file changes with StatReloader
INFO 2020-04-24 22:33:50,014 autoreload 222 /usr/src/app/apps/users/utils.py changed, reloading.
INFO 2020-04-24 22:33:51,399 autoreload 598 Watching for file changes with StatReloader
INFO 2020-04-24 22:52:25,714 autoreload 222 /usr/src/app/apps/users/utils.py changed, reloading.
INFO 2020-04-24 22:52:26,744 autoreload 598 Watching for file changes with StatReloader
INFO 2020-04-24 22:52:29,383 basehttp 157 "GET /admin/ HTTP/1.1" 200 2582
INFO 2020-04-24 22:52:29,451 basehttp 157 "GET /static/admin/css/responsive.css HTTP/1.1" 304 0
INFO 2020-04-24 22:52:29,452 basehttp 157 "GET /static/admin/css/dashboard.css HTTP/1.1" 304 0
INFO 2020-04-24 22:52:29,453 basehttp 157 "GET /static/admin/css/base.css HTTP/1.1" 304 0
INFO 2020-04-24 22:52:29,508 basehttp 157 "GET /static/admin/css/fonts.css HTTP/1.1" 304 0
INFO 2020-04-24 22:52:29,753 basehttp 157 "GET /static/admin/img/icon-changelink.svg HTTP/1.1" 304 0
INFO 2020-04-24 22:52:29,753 basehttp 157 "GET /static/admin/img/icon-addlink.svg HTTP/1.1" 304 0
INFO 2020-04-24 22:52:29,839 basehttp 157 "GET /static/admin/fonts/Roboto-Bold-webfont.woff HTTP/1.1" 304 0
INFO 2020-04-24 22:52:29,845 basehttp 157 "GET /static/admin/fonts/Roboto-Light-webfont.woff HTTP/1.1" 304 0
INFO 2020-04-24 22:52:29,847 basehttp 157 "GET /static/admin/fonts/Roboto-Regular-webfont.woff HTTP/1.1" 304 0
ERROR 2020-04-24 22:52:33,315 log 222 Internal Server Error: /users
Traceback (most recent call last):
  File "/usr/local/lib/python3.8/site-packages/rest_framework/views.py", line 502, in dispatch
    response = handler(request, *args, **kwargs)
  File "/usr/local/lib/python3.8/site-packages/rest_framework/views.py", line 167, in http_method_not_allowed
    raise exceptions.MethodNotAllowed(request.method)
rest_framework.exceptions.MethodNotAllowed: 方法 “GET” 不被允许。

During handling of the above exception, another exception occurred:

Traceback (most recent call last):
  File "/usr/local/lib/python3.8/site-packages/rest_framework/settings.py", line 177, in import_from_string
    return import_string(val)
  File "/usr/local/lib/python3.8/site-packages/django/utils/module_loading.py", line 17, in import_string
    module = import_module(module_path)
  File "/usr/local/lib/python3.8/importlib/__init__.py", line 127, in import_module
    return _bootstrap._gcd_import(name[level:], package, level)
  File "<frozen importlib._bootstrap>", line 1014, in _gcd_import
  File "<frozen importlib._bootstrap>", line 991, in _find_and_load
  File "<frozen importlib._bootstrap>", line 961, in _find_and_load_unlocked
  File "<frozen importlib._bootstrap>", line 219, in _call_with_frames_removed
  File "<frozen importlib._bootstrap>", line 1014, in _gcd_import
  File "<frozen importlib._bootstrap>", line 991, in _find_and_load
  File "<frozen importlib._bootstrap>", line 973, in _find_and_load_unlocked
ModuleNotFoundError: No module named 'src.utils'

During handling of the above exception, another exception occurred:

Traceback (most recent call last):
  File "/usr/local/lib/python3.8/site-packages/django/core/handlers/exception.py", line 34, in inner
    response = get_response(request)
  File "/usr/local/lib/python3.8/site-packages/django/core/handlers/base.py", line 115, in _get_response
    response = self.process_exception_by_middleware(e, request)
  File "/usr/local/lib/python3.8/site-packages/django/core/handlers/base.py", line 113, in _get_response
    response = wrapped_callback(request, *callback_args, **callback_kwargs)
  File "/usr/local/lib/python3.8/site-packages/django/views/decorators/csrf.py", line 54, in wrapped_view
    return view_func(*args, **kwargs)
  File "/usr/local/lib/python3.8/site-packages/django/views/generic/base.py", line 71, in view
    return self.dispatch(request, *args, **kwargs)
  File "/usr/local/lib/python3.8/site-packages/rest_framework/views.py", line 505, in dispatch
    response = self.handle_exception(exc)
  File "/usr/local/lib/python3.8/site-packages/rest_framework/views.py", line 459, in handle_exception
    exception_handler = self.get_exception_handler()
  File "/usr/local/lib/python3.8/site-packages/rest_framework/views.py", line 298, in get_exception_handler
    return self.settings.EXCEPTION_HANDLER
  File "/usr/local/lib/python3.8/site-packages/rest_framework/settings.py", line 220, in __getattr__
    val = perform_import(val, attr)
  File "/usr/local/lib/python3.8/site-packages/rest_framework/settings.py", line 166, in perform_import
    return import_from_string(val, setting_name)
  File "/usr/local/lib/python3.8/site-packages/rest_framework/settings.py", line 180, in import_from_string
    raise ImportError(msg)
ImportError: Could not import 'src.utils.exceptions.exception_handler' for API setting 'EXCEPTION_HANDLER'. ModuleNotFoundError: No module named 'src.utils'.
ERROR 2020-04-24 22:52:33,333 basehttp 157 "GET /users HTTP/1.1" 500 130450
INFO 2020-04-24 22:58:55,617 autoreload 222 /usr/src/app/src/settings.py changed, reloading.
INFO 2020-04-24 22:58:56,634 autoreload 598 Watching for file changes with StatReloader
ERROR 2020-04-24 22:59:01,386 log 222 Internal Server Error: /users
Traceback (most recent call last):
  File "/usr/local/lib/python3.8/site-packages/rest_framework/views.py", line 502, in dispatch
    response = handler(request, *args, **kwargs)
  File "/usr/local/lib/python3.8/site-packages/rest_framework/views.py", line 167, in http_method_not_allowed
    raise exceptions.MethodNotAllowed(request.method)
rest_framework.exceptions.MethodNotAllowed: 方法 “GET” 不被允许。

During handling of the above exception, another exception occurred:

Traceback (most recent call last):
  File "/usr/local/lib/python3.8/site-packages/rest_framework/settings.py", line 177, in import_from_string
    return import_string(val)
  File "/usr/local/lib/python3.8/site-packages/django/utils/module_loading.py", line 17, in import_string
    module = import_module(module_path)
  File "/usr/local/lib/python3.8/importlib/__init__.py", line 127, in import_module
    return _bootstrap._gcd_import(name[level:], package, level)
  File "<frozen importlib._bootstrap>", line 1014, in _gcd_import
  File "<frozen importlib._bootstrap>", line 991, in _find_and_load
  File "<frozen importlib._bootstrap>", line 961, in _find_and_load_unlocked
  File "<frozen importlib._bootstrap>", line 219, in _call_with_frames_removed
  File "<frozen importlib._bootstrap>", line 1014, in _gcd_import
  File "<frozen importlib._bootstrap>", line 991, in _find_and_load
  File "<frozen importlib._bootstrap>", line 961, in _find_and_load_unlocked
  File "<frozen importlib._bootstrap>", line 219, in _call_with_frames_removed
  File "<frozen importlib._bootstrap>", line 1014, in _gcd_import
  File "<frozen importlib._bootstrap>", line 991, in _find_and_load
  File "<frozen importlib._bootstrap>", line 973, in _find_and_load_unlocked
ModuleNotFoundError: No module named 'src.src'

During handling of the above exception, another exception occurred:

Traceback (most recent call last):
  File "/usr/local/lib/python3.8/site-packages/django/core/handlers/exception.py", line 34, in inner
    response = get_response(request)
  File "/usr/local/lib/python3.8/site-packages/django/core/handlers/base.py", line 115, in _get_response
    response = self.process_exception_by_middleware(e, request)
  File "/usr/local/lib/python3.8/site-packages/django/core/handlers/base.py", line 113, in _get_response
    response = wrapped_callback(request, *callback_args, **callback_kwargs)
  File "/usr/local/lib/python3.8/site-packages/django/views/decorators/csrf.py", line 54, in wrapped_view
    return view_func(*args, **kwargs)
  File "/usr/local/lib/python3.8/site-packages/django/views/generic/base.py", line 71, in view
    return self.dispatch(request, *args, **kwargs)
  File "/usr/local/lib/python3.8/site-packages/rest_framework/views.py", line 505, in dispatch
    response = self.handle_exception(exc)
  File "/usr/local/lib/python3.8/site-packages/rest_framework/views.py", line 459, in handle_exception
    exception_handler = self.get_exception_handler()
  File "/usr/local/lib/python3.8/site-packages/rest_framework/views.py", line 298, in get_exception_handler
    return self.settings.EXCEPTION_HANDLER
  File "/usr/local/lib/python3.8/site-packages/rest_framework/settings.py", line 220, in __getattr__
    val = perform_import(val, attr)
  File "/usr/local/lib/python3.8/site-packages/rest_framework/settings.py", line 166, in perform_import
    return import_from_string(val, setting_name)
  File "/usr/local/lib/python3.8/site-packages/rest_framework/settings.py", line 180, in import_from_string
    raise ImportError(msg)
ImportError: Could not import 'src.src.utils.exceptions.exception_handler' for API setting 'EXCEPTION_HANDLER'. ModuleNotFoundError: No module named 'src.src'.
ERROR 2020-04-24 22:59:01,391 basehttp 157 "GET /users HTTP/1.1" 500 137528
INFO 2020-04-24 22:59:14,683 autoreload 222 /usr/src/app/src/settings.py changed, reloading.
INFO 2020-04-24 22:59:15,705 autoreload 598 Watching for file changes with StatReloader
ERROR 2020-04-24 22:59:19,972 log 222 Internal Server Error: /users
Traceback (most recent call last):
  File "/usr/local/lib/python3.8/site-packages/rest_framework/views.py", line 502, in dispatch
    response = handler(request, *args, **kwargs)
  File "/usr/local/lib/python3.8/site-packages/rest_framework/views.py", line 167, in http_method_not_allowed
    raise exceptions.MethodNotAllowed(request.method)
rest_framework.exceptions.MethodNotAllowed: 方法 “GET” 不被允许。

During handling of the above exception, another exception occurred:

Traceback (most recent call last):
  File "/usr/local/lib/python3.8/site-packages/rest_framework/settings.py", line 177, in import_from_string
    return import_string(val)
  File "/usr/local/lib/python3.8/site-packages/django/utils/module_loading.py", line 17, in import_string
    module = import_module(module_path)
  File "/usr/local/lib/python3.8/importlib/__init__.py", line 127, in import_module
    return _bootstrap._gcd_import(name[level:], package, level)
  File "<frozen importlib._bootstrap>", line 1014, in _gcd_import
  File "<frozen importlib._bootstrap>", line 991, in _find_and_load
  File "<frozen importlib._bootstrap>", line 961, in _find_and_load_unlocked
  File "<frozen importlib._bootstrap>", line 219, in _call_with_frames_removed
  File "<frozen importlib._bootstrap>", line 1014, in _gcd_import
  File "<frozen importlib._bootstrap>", line 991, in _find_and_load
  File "<frozen importlib._bootstrap>", line 961, in _find_and_load_unlocked
  File "<frozen importlib._bootstrap>", line 219, in _call_with_frames_removed
  File "<frozen importlib._bootstrap>", line 1014, in _gcd_import
  File "<frozen importlib._bootstrap>", line 991, in _find_and_load
  File "<frozen importlib._bootstrap>", line 961, in _find_and_load_unlocked
  File "<frozen importlib._bootstrap>", line 219, in _call_with_frames_removed
  File "<frozen importlib._bootstrap>", line 1014, in _gcd_import
  File "<frozen importlib._bootstrap>", line 991, in _find_and_load
  File "<frozen importlib._bootstrap>", line 973, in _find_and_load_unlocked
ModuleNotFoundError: No module named 'app'

During handling of the above exception, another exception occurred:

Traceback (most recent call last):
  File "/usr/local/lib/python3.8/site-packages/django/core/handlers/exception.py", line 34, in inner
    response = get_response(request)
  File "/usr/local/lib/python3.8/site-packages/django/core/handlers/base.py", line 115, in _get_response
    response = self.process_exception_by_middleware(e, request)
  File "/usr/local/lib/python3.8/site-packages/django/core/handlers/base.py", line 113, in _get_response
    response = wrapped_callback(request, *callback_args, **callback_kwargs)
  File "/usr/local/lib/python3.8/site-packages/django/views/decorators/csrf.py", line 54, in wrapped_view
    return view_func(*args, **kwargs)
  File "/usr/local/lib/python3.8/site-packages/django/views/generic/base.py", line 71, in view
    return self.dispatch(request, *args, **kwargs)
  File "/usr/local/lib/python3.8/site-packages/rest_framework/views.py", line 505, in dispatch
    response = self.handle_exception(exc)
  File "/usr/local/lib/python3.8/site-packages/rest_framework/views.py", line 459, in handle_exception
    exception_handler = self.get_exception_handler()
  File "/usr/local/lib/python3.8/site-packages/rest_framework/views.py", line 298, in get_exception_handler
    return self.settings.EXCEPTION_HANDLER
  File "/usr/local/lib/python3.8/site-packages/rest_framework/settings.py", line 220, in __getattr__
    val = perform_import(val, attr)
  File "/usr/local/lib/python3.8/site-packages/rest_framework/settings.py", line 166, in perform_import
    return import_from_string(val, setting_name)
  File "/usr/local/lib/python3.8/site-packages/rest_framework/settings.py", line 180, in import_from_string
    raise ImportError(msg)
ImportError: Could not import 'app.src.utils.exceptions.exception_handler' for API setting 'EXCEPTION_HANDLER'. ModuleNotFoundError: No module named 'app'.
ERROR 2020-04-24 22:59:19,976 basehttp 157 "GET /users HTTP/1.1" 500 144079
INFO 2020-04-24 22:59:46,457 autoreload 222 /usr/src/app/src/settings.py changed, reloading.
INFO 2020-04-24 22:59:49,462 autoreload 598 Watching for file changes with StatReloader
ERROR 2020-04-24 23:00:17,080 log 222 Internal Server Error: /users
Traceback (most recent call last):
  File "/usr/local/lib/python3.8/site-packages/rest_framework/views.py", line 502, in dispatch
    response = handler(request, *args, **kwargs)
  File "/usr/local/lib/python3.8/site-packages/rest_framework/generics.py", line 190, in post
    return self.create(request, *args, **kwargs)
  File "/usr/local/lib/python3.8/site-packages/rest_framework/mixins.py", line 18, in create
    serializer.is_valid(raise_exception=True)
  File "/usr/local/lib/python3.8/site-packages/rest_framework/serializers.py", line 234, in is_valid
    self._validated_data = self.run_validation(self.initial_data)
  File "/usr/local/lib/python3.8/site-packages/rest_framework/serializers.py", line 433, in run_validation
    value = self.to_internal_value(data)
  File "/usr/local/lib/python3.8/site-packages/rest_framework/serializers.py", line 486, in to_internal_value
    for field in fields:
  File "/usr/local/lib/python3.8/site-packages/rest_framework/serializers.py", line 369, in _writable_fields
    for field in self.fields.values():
  File "/usr/local/lib/python3.8/site-packages/django/utils/functional.py", line 48, in __get__
    res = instance.__dict__[self.name] = self.func(instance)
  File "/usr/local/lib/python3.8/site-packages/rest_framework/serializers.py", line 363, in fields
    for key, value in self.get_fields().items():
  File "/usr/local/lib/python3.8/site-packages/rest_framework/serializers.py", line 1062, in get_fields
    field_class, field_kwargs = self.build_field(
  File "/usr/local/lib/python3.8/site-packages/rest_framework/serializers.py", line 1208, in build_field
    return self.build_unknown_field(field_name, model_class)
  File "/usr/local/lib/python3.8/site-packages/rest_framework/serializers.py", line 1323, in build_unknown_field
    raise ImproperlyConfigured(
django.core.exceptions.ImproperlyConfigured: Field name `passwrod` is not valid for model `User`.

During handling of the above exception, another exception occurred:

Traceback (most recent call last):
  File "/usr/local/lib/python3.8/site-packages/rest_framework/settings.py", line 177, in import_from_string
    return import_string(val)
  File "/usr/local/lib/python3.8/site-packages/django/utils/module_loading.py", line 17, in import_string
    module = import_module(module_path)
  File "/usr/local/lib/python3.8/importlib/__init__.py", line 127, in import_module
    return _bootstrap._gcd_import(name[level:], package, level)
  File "<frozen importlib._bootstrap>", line 1014, in _gcd_import
  File "<frozen importlib._bootstrap>", line 991, in _find_and_load
  File "<frozen importlib._bootstrap>", line 961, in _find_and_load_unlocked
  File "<frozen importlib._bootstrap>", line 219, in _call_with_frames_removed
  File "<frozen importlib._bootstrap>", line 1014, in _gcd_import
  File "<frozen importlib._bootstrap>", line 991, in _find_and_load
  File "<frozen importlib._bootstrap>", line 973, in _find_and_load_unlocked
ModuleNotFoundError: No module named 'src.utils'

During handling of the above exception, another exception occurred:

Traceback (most recent call last):
  File "/usr/local/lib/python3.8/site-packages/django/core/handlers/exception.py", line 34, in inner
    response = get_response(request)
  File "/usr/local/lib/python3.8/site-packages/django/core/handlers/base.py", line 115, in _get_response
    response = self.process_exception_by_middleware(e, request)
  File "/usr/local/lib/python3.8/site-packages/django/core/handlers/base.py", line 113, in _get_response
    response = wrapped_callback(request, *callback_args, **callback_kwargs)
  File "/usr/local/lib/python3.8/site-packages/django/views/decorators/csrf.py", line 54, in wrapped_view
    return view_func(*args, **kwargs)
  File "/usr/local/lib/python3.8/site-packages/django/views/generic/base.py", line 71, in view
    return self.dispatch(request, *args, **kwargs)
  File "/usr/local/lib/python3.8/site-packages/rest_framework/views.py", line 505, in dispatch
    response = self.handle_exception(exc)
  File "/usr/local/lib/python3.8/site-packages/rest_framework/views.py", line 459, in handle_exception
    exception_handler = self.get_exception_handler()
  File "/usr/local/lib/python3.8/site-packages/rest_framework/views.py", line 298, in get_exception_handler
    return self.settings.EXCEPTION_HANDLER
  File "/usr/local/lib/python3.8/site-packages/rest_framework/settings.py", line 220, in __getattr__
    val = perform_import(val, attr)
  File "/usr/local/lib/python3.8/site-packages/rest_framework/settings.py", line 166, in perform_import
    return import_from_string(val, setting_name)
  File "/usr/local/lib/python3.8/site-packages/rest_framework/settings.py", line 180, in import_from_string
    raise ImportError(msg)
ImportError: Could not import 'src.utils.exceptions.exception_handler' for API setting 'EXCEPTION_HANDLER'. ModuleNotFoundError: No module named 'src.utils'.
ERROR 2020-04-24 23:00:17,084 basehttp 157 "POST /users HTTP/1.1" 500 181393
INFO 2020-04-24 23:01:30,421 autoreload 222 /usr/src/app/apps/users/urls.py changed, reloading.
INFO 2020-04-24 23:01:31,583 autoreload 598 Watching for file changes with StatReloader
ERROR 2020-04-24 23:01:32,418 log 222 Internal Server Error: /users
Traceback (most recent call last):
  File "/usr/local/lib/python3.8/site-packages/django/core/handlers/exception.py", line 34, in inner
    response = get_response(request)
  File "/usr/local/lib/python3.8/site-packages/django/utils/deprecation.py", line 93, in __call__
    response = self.process_request(request)
  File "/usr/local/lib/python3.8/site-packages/django/middleware/common.py", line 54, in process_request
    path = self.get_full_path_with_slash(request)
  File "/usr/local/lib/python3.8/site-packages/django/middleware/common.py", line 87, in get_full_path_with_slash
    raise RuntimeError(
RuntimeError: You called this URL via POST, but the URL doesn't end in a slash and you have APPEND_SLASH set. Django can't redirect to the slash URL while maintaining POST data. Change your form to point to 192.168.148.129:8000/users/ (note the trailing slash), or set APPEND_SLASH=False in your Django settings.
ERROR 2020-04-24 23:01:32,424 basehttp 157 "POST /users HTTP/1.1" 500 65317
ERROR 2020-04-24 23:01:49,371 log 222 Internal Server Error: /users/
Traceback (most recent call last):
  File "/usr/local/lib/python3.8/site-packages/rest_framework/views.py", line 502, in dispatch
    response = handler(request, *args, **kwargs)
  File "/usr/local/lib/python3.8/site-packages/rest_framework/generics.py", line 190, in post
    return self.create(request, *args, **kwargs)
  File "/usr/local/lib/python3.8/site-packages/rest_framework/mixins.py", line 18, in create
    serializer.is_valid(raise_exception=True)
  File "/usr/local/lib/python3.8/site-packages/rest_framework/serializers.py", line 234, in is_valid
    self._validated_data = self.run_validation(self.initial_data)
  File "/usr/local/lib/python3.8/site-packages/rest_framework/serializers.py", line 433, in run_validation
    value = self.to_internal_value(data)
  File "/usr/local/lib/python3.8/site-packages/rest_framework/serializers.py", line 486, in to_internal_value
    for field in fields:
  File "/usr/local/lib/python3.8/site-packages/rest_framework/serializers.py", line 369, in _writable_fields
    for field in self.fields.values():
  File "/usr/local/lib/python3.8/site-packages/django/utils/functional.py", line 48, in __get__
    res = instance.__dict__[self.name] = self.func(instance)
  File "/usr/local/lib/python3.8/site-packages/rest_framework/serializers.py", line 363, in fields
    for key, value in self.get_fields().items():
  File "/usr/local/lib/python3.8/site-packages/rest_framework/serializers.py", line 1062, in get_fields
    field_class, field_kwargs = self.build_field(
  File "/usr/local/lib/python3.8/site-packages/rest_framework/serializers.py", line 1208, in build_field
    return self.build_unknown_field(field_name, model_class)
  File "/usr/local/lib/python3.8/site-packages/rest_framework/serializers.py", line 1323, in build_unknown_field
    raise ImproperlyConfigured(
django.core.exceptions.ImproperlyConfigured: Field name `passwrod` is not valid for model `User`.

During handling of the above exception, another exception occurred:

Traceback (most recent call last):
  File "/usr/local/lib/python3.8/site-packages/rest_framework/settings.py", line 177, in import_from_string
    return import_string(val)
  File "/usr/local/lib/python3.8/site-packages/django/utils/module_loading.py", line 17, in import_string
    module = import_module(module_path)
  File "/usr/local/lib/python3.8/importlib/__init__.py", line 127, in import_module
    return _bootstrap._gcd_import(name[level:], package, level)
  File "<frozen importlib._bootstrap>", line 1014, in _gcd_import
  File "<frozen importlib._bootstrap>", line 991, in _find_and_load
  File "<frozen importlib._bootstrap>", line 961, in _find_and_load_unlocked
  File "<frozen importlib._bootstrap>", line 219, in _call_with_frames_removed
  File "<frozen importlib._bootstrap>", line 1014, in _gcd_import
  File "<frozen importlib._bootstrap>", line 991, in _find_and_load
  File "<frozen importlib._bootstrap>", line 973, in _find_and_load_unlocked
ModuleNotFoundError: No module named 'src.utils'

During handling of the above exception, another exception occurred:

Traceback (most recent call last):
  File "/usr/local/lib/python3.8/site-packages/django/core/handlers/exception.py", line 34, in inner
    response = get_response(request)
  File "/usr/local/lib/python3.8/site-packages/django/core/handlers/base.py", line 115, in _get_response
    response = self.process_exception_by_middleware(e, request)
  File "/usr/local/lib/python3.8/site-packages/django/core/handlers/base.py", line 113, in _get_response
    response = wrapped_callback(request, *callback_args, **callback_kwargs)
  File "/usr/local/lib/python3.8/site-packages/django/views/decorators/csrf.py", line 54, in wrapped_view
    return view_func(*args, **kwargs)
  File "/usr/local/lib/python3.8/site-packages/django/views/generic/base.py", line 71, in view
    return self.dispatch(request, *args, **kwargs)
  File "/usr/local/lib/python3.8/site-packages/rest_framework/views.py", line 505, in dispatch
    response = self.handle_exception(exc)
  File "/usr/local/lib/python3.8/site-packages/rest_framework/views.py", line 459, in handle_exception
    exception_handler = self.get_exception_handler()
  File "/usr/local/lib/python3.8/site-packages/rest_framework/views.py", line 298, in get_exception_handler
    return self.settings.EXCEPTION_HANDLER
  File "/usr/local/lib/python3.8/site-packages/rest_framework/settings.py", line 220, in __getattr__
    val = perform_import(val, attr)
  File "/usr/local/lib/python3.8/site-packages/rest_framework/settings.py", line 166, in perform_import
    return import_from_string(val, setting_name)
  File "/usr/local/lib/python3.8/site-packages/rest_framework/settings.py", line 180, in import_from_string
    raise ImportError(msg)
ImportError: Could not import 'src.utils.exceptions.exception_handler' for API setting 'EXCEPTION_HANDLER'. ModuleNotFoundError: No module named 'src.utils'.
ERROR 2020-04-24 23:01:49,378 basehttp 157 "POST /users/ HTTP/1.1" 500 181407
INFO 2020-04-24 23:03:05,112 autoreload 222 /usr/src/app/src/settings.py changed, reloading.
INFO 2020-04-24 23:03:06,140 autoreload 598 Watching for file changes with StatReloader
ERROR 2020-04-24 23:03:10,036 log 222 Internal Server Error: /users/
Traceback (most recent call last):
  File "/usr/local/lib/python3.8/site-packages/django/core/handlers/exception.py", line 34, in inner
    response = get_response(request)
  File "/usr/local/lib/python3.8/site-packages/django/core/handlers/base.py", line 115, in _get_response
    response = self.process_exception_by_middleware(e, request)
  File "/usr/local/lib/python3.8/site-packages/django/core/handlers/base.py", line 113, in _get_response
    response = wrapped_callback(request, *callback_args, **callback_kwargs)
  File "/usr/local/lib/python3.8/site-packages/django/views/decorators/csrf.py", line 54, in wrapped_view
    return view_func(*args, **kwargs)
  File "/usr/local/lib/python3.8/site-packages/django/views/generic/base.py", line 71, in view
    return self.dispatch(request, *args, **kwargs)
  File "/usr/local/lib/python3.8/site-packages/rest_framework/views.py", line 505, in dispatch
    response = self.handle_exception(exc)
  File "/usr/local/lib/python3.8/site-packages/rest_framework/views.py", line 465, in handle_exception
    self.raise_uncaught_exception(exc)
  File "/usr/local/lib/python3.8/site-packages/rest_framework/views.py", line 476, in raise_uncaught_exception
    raise exc
  File "/usr/local/lib/python3.8/site-packages/rest_framework/views.py", line 502, in dispatch
    response = handler(request, *args, **kwargs)
  File "/usr/local/lib/python3.8/site-packages/rest_framework/generics.py", line 190, in post
    return self.create(request, *args, **kwargs)
  File "/usr/local/lib/python3.8/site-packages/rest_framework/mixins.py", line 18, in create
    serializer.is_valid(raise_exception=True)
  File "/usr/local/lib/python3.8/site-packages/rest_framework/serializers.py", line 234, in is_valid
    self._validated_data = self.run_validation(self.initial_data)
  File "/usr/local/lib/python3.8/site-packages/rest_framework/serializers.py", line 433, in run_validation
    value = self.to_internal_value(data)
  File "/usr/local/lib/python3.8/site-packages/rest_framework/serializers.py", line 486, in to_internal_value
    for field in fields:
  File "/usr/local/lib/python3.8/site-packages/rest_framework/serializers.py", line 369, in _writable_fields
    for field in self.fields.values():
  File "/usr/local/lib/python3.8/site-packages/django/utils/functional.py", line 48, in __get__
    res = instance.__dict__[self.name] = self.func(instance)
  File "/usr/local/lib/python3.8/site-packages/rest_framework/serializers.py", line 363, in fields
    for key, value in self.get_fields().items():
  File "/usr/local/lib/python3.8/site-packages/rest_framework/serializers.py", line 1062, in get_fields
    field_class, field_kwargs = self.build_field(
  File "/usr/local/lib/python3.8/site-packages/rest_framework/serializers.py", line 1208, in build_field
    return self.build_unknown_field(field_name, model_class)
  File "/usr/local/lib/python3.8/site-packages/rest_framework/serializers.py", line 1323, in build_unknown_field
    raise ImproperlyConfigured(
django.core.exceptions.ImproperlyConfigured: Field name `passwrod` is not valid for model `User`.
ERROR 2020-04-24 23:03:10,053 basehttp 157 "POST /users/ HTTP/1.1" 500 17150
INFO 2020-04-24 23:03:54,705 autoreload 222 /usr/src/app/apps/users/serializers.py changed, reloading.
INFO 2020-04-24 23:03:55,893 autoreload 598 Watching for file changes with StatReloader
WARNING 2020-04-24 23:03:56,783 log 222 Bad Request: /users/
WARNING 2020-04-24 23:03:56,784 basehttp 157 "POST /users/ HTTP/1.1" 400 162
INFO 2020-04-24 23:04:04,681 basehttp 157 "GET /users HTTP/1.1" 301 0
WARNING 2020-04-24 23:04:04,775 log 222 Method Not Allowed: /users/
WARNING 2020-04-24 23:04:04,776 basehttp 157 "GET /users/ HTTP/1.1" 405 8154
INFO 2020-04-24 23:04:04,822 basehttp 157 "GET /static/rest_framework/css/bootstrap-tweaks.css HTTP/1.1" 200 3385
INFO 2020-04-24 23:04:04,857 basehttp 157 "GET /static/rest_framework/css/default.css HTTP/1.1" 200 1131
INFO 2020-04-24 23:04:04,860 basehttp 157 "GET /static/rest_framework/css/prettify.css HTTP/1.1" 200 817
INFO 2020-04-24 23:04:04,870 basehttp 157 "GET /static/rest_framework/js/csrf.js HTTP/1.1" 200 1719
INFO 2020-04-24 23:04:04,872 basehttp 157 "GET /static/rest_framework/css/bootstrap.min.css HTTP/1.1" 200 121457
INFO 2020-04-24 23:04:04,884 basehttp 157 "GET /static/rest_framework/js/bootstrap.min.js HTTP/1.1" 200 39680
INFO 2020-04-24 23:04:04,891 basehttp 157 "GET /static/rest_framework/js/jquery-3.4.1.min.js HTTP/1.1" 200 88145
INFO 2020-04-24 23:04:04,899 basehttp 157 "GET /static/rest_framework/js/prettify-min.js HTTP/1.1" 200 13632
INFO 2020-04-24 23:04:04,902 basehttp 157 "GET /static/rest_framework/js/ajax-form.js HTTP/1.1" 200 3597
INFO 2020-04-24 23:04:04,920 basehttp 157 "GET /static/rest_framework/js/default.js HTTP/1.1" 200 1268
INFO 2020-04-24 23:04:04,953 basehttp 157 "GET /static/rest_framework/img/grid.png HTTP/1.1" 200 1458
ERROR 2020-04-24 23:04:56,341 log 222 Internal Server Error: /users/
Traceback (most recent call last):
  File "/usr/local/lib/python3.8/site-packages/django/core/handlers/exception.py", line 34, in inner
    response = get_response(request)
  File "/usr/local/lib/python3.8/site-packages/django/core/handlers/base.py", line 115, in _get_response
    response = self.process_exception_by_middleware(e, request)
  File "/usr/local/lib/python3.8/site-packages/django/core/handlers/base.py", line 113, in _get_response
    response = wrapped_callback(request, *callback_args, **callback_kwargs)
  File "/usr/local/lib/python3.8/site-packages/django/views/decorators/csrf.py", line 54, in wrapped_view
    return view_func(*args, **kwargs)
  File "/usr/local/lib/python3.8/site-packages/django/views/generic/base.py", line 71, in view
    return self.dispatch(request, *args, **kwargs)
  File "/usr/local/lib/python3.8/site-packages/rest_framework/views.py", line 505, in dispatch
    response = self.handle_exception(exc)
  File "/usr/local/lib/python3.8/site-packages/rest_framework/views.py", line 465, in handle_exception
    self.raise_uncaught_exception(exc)
  File "/usr/local/lib/python3.8/site-packages/rest_framework/views.py", line 476, in raise_uncaught_exception
    raise exc
  File "/usr/local/lib/python3.8/site-packages/rest_framework/views.py", line 502, in dispatch
    response = handler(request, *args, **kwargs)
  File "/usr/local/lib/python3.8/site-packages/rest_framework/generics.py", line 190, in post
    return self.create(request, *args, **kwargs)
  File "/usr/local/lib/python3.8/site-packages/rest_framework/mixins.py", line 18, in create
    serializer.is_valid(raise_exception=True)
  File "/usr/local/lib/python3.8/site-packages/rest_framework/serializers.py", line 234, in is_valid
    self._validated_data = self.run_validation(self.initial_data)
  File "/usr/local/lib/python3.8/site-packages/rest_framework/serializers.py", line 436, in run_validation
    value = self.validate(value)
  File "/usr/src/app/apps/users/serializers.py", line 52, in validate
    real_sms_code = SMSCodeView.check_SMSCode(attrs['mobile'])
KeyError: 'mobile'
ERROR 2020-04-24 23:04:56,345 basehttp 157 "POST /users/ HTTP/1.1" 500 116867
WARNING 2020-04-24 23:05:05,863 log 222 Method Not Allowed: /users/
WARNING 2020-04-24 23:05:05,865 basehttp 157 "GET /users/ HTTP/1.1" 405 8154
INFO 2020-04-24 23:05:08,951 basehttp 157 "OPTIONS /users/ HTTP/1.1" 200 10352
INFO 2020-04-24 23:05:33,084 basehttp 157 "OPTIONS /users/ HTTP/1.1" 200 10352
ERROR 2020-04-24 23:06:18,551 log 222 Internal Server Error: /users/
Traceback (most recent call last):
  File "/usr/local/lib/python3.8/site-packages/django/core/handlers/exception.py", line 34, in inner
    response = get_response(request)
  File "/usr/local/lib/python3.8/site-packages/django/core/handlers/base.py", line 115, in _get_response
    response = self.process_exception_by_middleware(e, request)
  File "/usr/local/lib/python3.8/site-packages/django/core/handlers/base.py", line 113, in _get_response
    response = wrapped_callback(request, *callback_args, **callback_kwargs)
  File "/usr/local/lib/python3.8/site-packages/django/views/decorators/csrf.py", line 54, in wrapped_view
    return view_func(*args, **kwargs)
  File "/usr/local/lib/python3.8/site-packages/django/views/generic/base.py", line 71, in view
    return self.dispatch(request, *args, **kwargs)
  File "/usr/local/lib/python3.8/site-packages/rest_framework/views.py", line 505, in dispatch
    response = self.handle_exception(exc)
  File "/usr/local/lib/python3.8/site-packages/rest_framework/views.py", line 465, in handle_exception
    self.raise_uncaught_exception(exc)
  File "/usr/local/lib/python3.8/site-packages/rest_framework/views.py", line 476, in raise_uncaught_exception
    raise exc
  File "/usr/local/lib/python3.8/site-packages/rest_framework/views.py", line 502, in dispatch
    response = handler(request, *args, **kwargs)
  File "/usr/local/lib/python3.8/site-packages/rest_framework/generics.py", line 190, in post
    return self.create(request, *args, **kwargs)
  File "/usr/local/lib/python3.8/site-packages/rest_framework/mixins.py", line 18, in create
    serializer.is_valid(raise_exception=True)
  File "/usr/local/lib/python3.8/site-packages/rest_framework/serializers.py", line 234, in is_valid
    self._validated_data = self.run_validation(self.initial_data)
  File "/usr/local/lib/python3.8/site-packages/rest_framework/serializers.py", line 436, in run_validation
    value = self.validate(value)
  File "/usr/src/app/apps/users/serializers.py", line 52, in validate
    real_sms_code = SMSCodeView.check_SMSCode(attrs['mobile'])
KeyError: 'mobile'
ERROR 2020-04-24 23:06:18,558 basehttp 157 "POST /users/ HTTP/1.1" 500 115426
INFO 2020-04-24 23:07:00,075 basehttp 157 "GET /image_codes/1 HTTP/1.1" 301 0
INFO 2020-04-24 23:07:00,178 basehttp 157 "GET /image_codes/1/ HTTP/1.1" 200 3240
INFO 2020-04-24 23:07:16,363 basehttp 157 "GET /sms_code/15850530699?image_code=5bd7&uuid=1 HTTP/1.1" 301 0
INFO 2020-04-24 23:07:16,663 basehttp 157 "GET /sms_code/15850530699/?image_code=5bd7&uuid=1 HTTP/1.1" 200 29
INFO 2020-04-24 23:07:22,004 tasks 24 发送短信验证码[正常][mobile: 15850530699]
INFO 2020-04-24 23:07:24,131 basehttp 157 "GET /admin/ HTTP/1.1" 200 2582
WARNING 2020-04-24 23:07:25,443 log 222 Method Not Allowed: /users/
WARNING 2020-04-24 23:07:25,444 basehttp 157 "GET /users/ HTTP/1.1" 405 8154
ERROR 2020-04-24 23:07:58,996 log 222 Internal Server Error: /users/
Traceback (most recent call last):
  File "/usr/local/lib/python3.8/site-packages/django/core/handlers/exception.py", line 34, in inner
    response = get_response(request)
  File "/usr/local/lib/python3.8/site-packages/django/core/handlers/base.py", line 115, in _get_response
    response = self.process_exception_by_middleware(e, request)
  File "/usr/local/lib/python3.8/site-packages/django/core/handlers/base.py", line 113, in _get_response
    response = wrapped_callback(request, *callback_args, **callback_kwargs)
  File "/usr/local/lib/python3.8/site-packages/django/views/decorators/csrf.py", line 54, in wrapped_view
    return view_func(*args, **kwargs)
  File "/usr/local/lib/python3.8/site-packages/django/views/generic/base.py", line 71, in view
    return self.dispatch(request, *args, **kwargs)
  File "/usr/local/lib/python3.8/site-packages/rest_framework/views.py", line 505, in dispatch
    response = self.handle_exception(exc)
  File "/usr/local/lib/python3.8/site-packages/rest_framework/views.py", line 465, in handle_exception
    self.raise_uncaught_exception(exc)
  File "/usr/local/lib/python3.8/site-packages/rest_framework/views.py", line 476, in raise_uncaught_exception
    raise exc
  File "/usr/local/lib/python3.8/site-packages/rest_framework/views.py", line 502, in dispatch
    response = handler(request, *args, **kwargs)
  File "/usr/local/lib/python3.8/site-packages/rest_framework/generics.py", line 190, in post
    return self.create(request, *args, **kwargs)
  File "/usr/local/lib/python3.8/site-packages/rest_framework/mixins.py", line 18, in create
    serializer.is_valid(raise_exception=True)
  File "/usr/local/lib/python3.8/site-packages/rest_framework/serializers.py", line 234, in is_valid
    self._validated_data = self.run_validation(self.initial_data)
  File "/usr/local/lib/python3.8/site-packages/rest_framework/serializers.py", line 436, in run_validation
    value = self.validate(value)
  File "/usr/src/app/apps/users/serializers.py", line 52, in validate
    real_sms_code = SMSCodeView.check_SMSCode(attrs['mobile'])
KeyError: 'mobile'
ERROR 2020-04-24 23:07:58,997 basehttp 157 "POST /users/ HTTP/1.1" 500 115426
INFO 2020-04-24 23:08:32,038 autoreload 222 /usr/src/app/apps/users/serializers.py changed, reloading.
INFO 2020-04-24 23:08:33,107 autoreload 598 Watching for file changes with StatReloader
INFO 2020-04-24 23:08:45,741 basehttp 157 "GET /admin/ HTTP/1.1" 200 2582
WARNING 2020-04-24 23:09:04,504 log 222 Method Not Allowed: /users/
WARNING 2020-04-24 23:09:04,505 basehttp 157 "GET /users/ HTTP/1.1" 405 8438
ERROR 2020-04-24 23:09:29,895 log 222 Internal Server Error: /users/
Traceback (most recent call last):
  File "/usr/local/lib/python3.8/site-packages/django/core/handlers/exception.py", line 34, in inner
    response = get_response(request)
  File "/usr/local/lib/python3.8/site-packages/django/core/handlers/base.py", line 115, in _get_response
    response = self.process_exception_by_middleware(e, request)
  File "/usr/local/lib/python3.8/site-packages/django/core/handlers/base.py", line 113, in _get_response
    response = wrapped_callback(request, *callback_args, **callback_kwargs)
  File "/usr/local/lib/python3.8/site-packages/django/views/decorators/csrf.py", line 54, in wrapped_view
    return view_func(*args, **kwargs)
  File "/usr/local/lib/python3.8/site-packages/django/views/generic/base.py", line 71, in view
    return self.dispatch(request, *args, **kwargs)
  File "/usr/local/lib/python3.8/site-packages/rest_framework/views.py", line 505, in dispatch
    response = self.handle_exception(exc)
  File "/usr/local/lib/python3.8/site-packages/rest_framework/views.py", line 465, in handle_exception
    self.raise_uncaught_exception(exc)
  File "/usr/local/lib/python3.8/site-packages/rest_framework/views.py", line 476, in raise_uncaught_exception
    raise exc
  File "/usr/local/lib/python3.8/site-packages/rest_framework/views.py", line 502, in dispatch
    response = handler(request, *args, **kwargs)
  File "/usr/local/lib/python3.8/site-packages/rest_framework/generics.py", line 190, in post
    return self.create(request, *args, **kwargs)
  File "/usr/local/lib/python3.8/site-packages/rest_framework/mixins.py", line 18, in create
    serializer.is_valid(raise_exception=True)
  File "/usr/local/lib/python3.8/site-packages/rest_framework/serializers.py", line 234, in is_valid
    self._validated_data = self.run_validation(self.initial_data)
  File "/usr/local/lib/python3.8/site-packages/rest_framework/serializers.py", line 436, in run_validation
    value = self.validate(value)
  File "/usr/src/app/apps/users/serializers.py", line 52, in validate
    real_sms_code = SMSCodeView.check_SMSCode(attrs['mobile'])
  File "/usr/src/app/apps/verifications/views.py", line 85, in check_SMSCode
    real_sms = conn.get(f'sms_code_{mobile}').decode()
AttributeError: 'NoneType' object has no attribute 'decode'
ERROR 2020-04-24 23:09:29,909 basehttp 157 "POST /users/ HTTP/1.1" 500 121768
INFO 2020-04-24 23:09:39,544 basehttp 157 "GET /image_codes/1 HTTP/1.1" 301 0
INFO 2020-04-24 23:09:39,619 basehttp 157 "GET /image_codes/1/ HTTP/1.1" 200 3572
INFO 2020-04-24 23:09:47,433 basehttp 157 "GET /sms_code/15850530699?image_code=isrm&uuid=1 HTTP/1.1" 301 0
INFO 2020-04-24 23:09:47,769 basehttp 157 "GET /sms_code/15850530699/?image_code=isrm&uuid=1 HTTP/1.1" 200 29
INFO 2020-04-24 23:09:52,962 tasks 24 发送短信验证码[正常][mobile: 15850530699]
WARNING 2020-04-24 23:10:01,600 log 222 Bad Request: /users/
WARNING 2020-04-24 23:10:01,601 basehttp 157 "POST /users/ HTTP/1.1" 400 8628
INFO 2020-04-24 23:10:07,300 basehttp 157 "GET /sms_code/15850530699?image_code=isrm&uuid=1 HTTP/1.1" 301 0
WARNING 2020-04-24 23:10:07,345 log 222 Bad Request: /sms_code/15850530699/
WARNING 2020-04-24 23:10:07,346 basehttp 157 "GET /sms_code/15850530699/?image_code=isrm&uuid=1 HTTP/1.1" 400 51
INFO 2020-04-24 23:10:09,978 basehttp 157 "GET /image_codes/1 HTTP/1.1" 301 0
INFO 2020-04-24 23:10:10,031 basehttp 157 "GET /image_codes/1/ HTTP/1.1" 200 3117
INFO 2020-04-24 23:10:17,140 basehttp 157 "GET /sms_code/15850530699?image_code=kqk5&uuid=1 HTTP/1.1" 301 0
WARNING 2020-04-24 23:10:17,185 log 222 Bad Request: /sms_code/15850530699/
WARNING 2020-04-24 23:10:17,185 basehttp 157 "GET /sms_code/15850530699/?image_code=kqk5&uuid=1 HTTP/1.1" 400 51
INFO 2020-04-24 23:10:21,065 basehttp 157 "GET /sms_code/15850530699?image_code=kqk5&uuid=1 HTTP/1.1" 301 0
WARNING 2020-04-24 23:10:21,111 log 222 Bad Request: /sms_code/15850530699/
WARNING 2020-04-24 23:10:21,112 basehttp 157 "GET /sms_code/15850530699/?image_code=kqk5&uuid=1 HTTP/1.1" 400 51
INFO 2020-04-24 23:10:22,005 basehttp 157 "GET /sms_code/15850530699?image_code=kqk5&uuid=1 HTTP/1.1" 301 0
WARNING 2020-04-24 23:10:22,052 log 222 Bad Request: /sms_code/15850530699/
WARNING 2020-04-24 23:10:22,053 basehttp 157 "GET /sms_code/15850530699/?image_code=kqk5&uuid=1 HTTP/1.1" 400 51
INFO 2020-04-24 23:10:22,666 basehttp 157 "GET /sms_code/15850530699?image_code=kqk5&uuid=1 HTTP/1.1" 301 0
WARNING 2020-04-24 23:10:22,711 log 222 Bad Request: /sms_code/15850530699/
WARNING 2020-04-24 23:10:22,711 basehttp 157 "GET /sms_code/15850530699/?image_code=kqk5&uuid=1 HTTP/1.1" 400 51
INFO 2020-04-24 23:10:23,275 basehttp 157 "GET /sms_code/15850530699?image_code=kqk5&uuid=1 HTTP/1.1" 301 0
WARNING 2020-04-24 23:10:23,322 log 222 Bad Request: /sms_code/15850530699/
WARNING 2020-04-24 23:10:23,323 basehttp 157 "GET /sms_code/15850530699/?image_code=kqk5&uuid=1 HTTP/1.1" 400 51
INFO 2020-04-24 23:10:23,859 basehttp 157 "GET /sms_code/15850530699?image_code=kqk5&uuid=1 HTTP/1.1" 301 0
WARNING 2020-04-24 23:10:23,903 log 222 Bad Request: /sms_code/15850530699/
WARNING 2020-04-24 23:10:23,904 basehttp 157 "GET /sms_code/15850530699/?image_code=kqk5&uuid=1 HTTP/1.1" 400 51
INFO 2020-04-24 23:10:24,470 basehttp 157 "GET /sms_code/15850530699?image_code=kqk5&uuid=1 HTTP/1.1" 301 0
WARNING 2020-04-24 23:10:24,517 log 222 Bad Request: /sms_code/15850530699/
WARNING 2020-04-24 23:10:24,518 basehttp 157 "GET /sms_code/15850530699/?image_code=kqk5&uuid=1 HTTP/1.1" 400 51
INFO 2020-04-24 23:10:25,109 basehttp 157 "GET /sms_code/15850530699?image_code=kqk5&uuid=1 HTTP/1.1" 301 0
WARNING 2020-04-24 23:10:25,151 log 222 Bad Request: /sms_code/15850530699/
WARNING 2020-04-24 23:10:25,152 basehttp 157 "GET /sms_code/15850530699/?image_code=kqk5&uuid=1 HTTP/1.1" 400 51
INFO 2020-04-24 23:10:47,895 basehttp 157 "GET /sms_code/15850530699?image_code=kqk5&uuid=1 HTTP/1.1" 301 0
INFO 2020-04-24 23:10:47,969 basehttp 157 "GET /sms_code/15850530699/?image_code=kqk5&uuid=1 HTTP/1.1" 200 29
INFO 2020-04-24 23:10:53,180 tasks 24 发送短信验证码[正常][mobile: 15850530699]
ERROR 2020-04-24 23:11:02,215 log 222 Internal Server Error: /users/
Traceback (most recent call last):
  File "/usr/local/lib/python3.8/site-packages/django/core/handlers/exception.py", line 34, in inner
    response = get_response(request)
  File "/usr/local/lib/python3.8/site-packages/django/core/handlers/base.py", line 115, in _get_response
    response = self.process_exception_by_middleware(e, request)
  File "/usr/local/lib/python3.8/site-packages/django/core/handlers/base.py", line 113, in _get_response
    response = wrapped_callback(request, *callback_args, **callback_kwargs)
  File "/usr/local/lib/python3.8/site-packages/django/views/decorators/csrf.py", line 54, in wrapped_view
    return view_func(*args, **kwargs)
  File "/usr/local/lib/python3.8/site-packages/django/views/generic/base.py", line 71, in view
    return self.dispatch(request, *args, **kwargs)
  File "/usr/local/lib/python3.8/site-packages/rest_framework/views.py", line 505, in dispatch
    response = self.handle_exception(exc)
  File "/usr/local/lib/python3.8/site-packages/rest_framework/views.py", line 465, in handle_exception
    self.raise_uncaught_exception(exc)
  File "/usr/local/lib/python3.8/site-packages/rest_framework/views.py", line 476, in raise_uncaught_exception
    raise exc
  File "/usr/local/lib/python3.8/site-packages/rest_framework/views.py", line 502, in dispatch
    response = handler(request, *args, **kwargs)
  File "/usr/local/lib/python3.8/site-packages/rest_framework/generics.py", line 190, in post
    return self.create(request, *args, **kwargs)
  File "/usr/local/lib/python3.8/site-packages/rest_framework/mixins.py", line 18, in create
    serializer.is_valid(raise_exception=True)
  File "/usr/local/lib/python3.8/site-packages/rest_framework/serializers.py", line 234, in is_valid
    self._validated_data = self.run_validation(self.initial_data)
  File "/usr/local/lib/python3.8/site-packages/rest_framework/serializers.py", line 436, in run_validation
    value = self.validate(value)
  File "/usr/src/app/apps/users/serializers.py", line 52, in validate
    real_sms_code = SMSCodeView.check_SMSCode(attrs['mobile'])
  File "/usr/src/app/apps/verifications/views.py", line 85, in check_SMSCode
    real_sms = conn.get(f'sms_code_{mobile}').decode()
AttributeError: 'NoneType' object has no attribute 'decode'
ERROR 2020-04-24 23:11:02,222 basehttp 157 "POST /users/ HTTP/1.1" 500 121768
INFO 2020-04-24 23:12:41,078 autoreload 222 /usr/src/app/apps/verifications/views.py changed, reloading.
INFO 2020-04-24 23:12:42,185 autoreload 598 Watching for file changes with StatReloader
INFO 2020-04-24 23:12:43,286 basehttp 157 "GET /image_codes/1 HTTP/1.1" 301 0
INFO 2020-04-24 23:12:43,376 basehttp 157 "GET /image_codes/1/ HTTP/1.1" 200 3060
INFO 2020-04-24 23:12:55,642 basehttp 157 "GET /sms_code/15850530699?image_code=3xjf&uuid=1 HTTP/1.1" 301 0
WARNING 2020-04-24 23:12:55,689 log 222 Bad Request: /sms_code/15850530699/
WARNING 2020-04-24 23:12:55,696 basehttp 157 "GET /sms_code/15850530699/?image_code=3xjf&uuid=1 HTTP/1.1" 400 48
INFO 2020-04-24 23:13:30,514 basehttp 157 "GET /image_codes/1 HTTP/1.1" 301 0
INFO 2020-04-24 23:13:30,568 basehttp 157 "GET /image_codes/1/ HTTP/1.1" 200 3378
INFO 2020-04-24 23:13:38,858 basehttp 157 "GET /sms_code/15850530699?image_code=gria&uuid=1 HTTP/1.1" 301 0
WARNING 2020-04-24 23:13:38,905 log 222 Bad Request: /sms_code/15850530699/
WARNING 2020-04-24 23:13:38,906 basehttp 157 "GET /sms_code/15850530699/?image_code=gria&uuid=1 HTTP/1.1" 400 48
INFO 2020-04-24 23:14:08,338 basehttp 157 "GET /image_codes/1 HTTP/1.1" 301 0
INFO 2020-04-24 23:14:08,393 basehttp 157 "GET /image_codes/1/ HTTP/1.1" 200 3422
INFO 2020-04-24 23:14:15,480 basehttp 157 "GET /sms_code/15850530699?image_code=eigk&uuid=1 HTTP/1.1" 301 0
WARNING 2020-04-24 23:14:15,586 log 222 Bad Request: /sms_code/15850530699/
WARNING 2020-04-24 23:14:15,587 basehttp 157 "GET /sms_code/15850530699/?image_code=eigk&uuid=1 HTTP/1.1" 400 48
INFO 2020-04-24 23:20:13,370 basehttp 157 "GET /image_codes/1 HTTP/1.1" 301 0
INFO 2020-04-24 23:20:13,428 basehttp 157 "GET /image_codes/1/ HTTP/1.1" 200 2796
INFO 2020-04-24 23:20:28,279 basehttp 157 "GET /sms_code/15850530699?image_code=bqjv&uuid=1 HTTP/1.1" 301 0
WARNING 2020-04-24 23:20:28,324 log 222 Bad Request: /sms_code/15850530699/
WARNING 2020-04-24 23:20:28,326 basehttp 157 "GET /sms_code/15850530699/?image_code=bqjv&uuid=1 HTTP/1.1" 400 48
INFO 2020-04-24 23:20:32,955 basehttp 157 "GET /sms_code/15850530699?image_code=bqjv&uuid=1 HTTP/1.1" 301 0
INFO 2020-04-24 23:20:33,007 basehttp 157 "GET /sms_code/15850530699/?image_code=bqjv&uuid=1 HTTP/1.1" 200 72
INFO 2020-04-24 23:20:41,247 basehttp 157 "GET /image_codes/1 HTTP/1.1" 301 0
INFO 2020-04-24 23:20:41,301 basehttp 157 "GET /image_codes/1/ HTTP/1.1" 200 3394
INFO 2020-04-24 23:20:52,052 basehttp 157 "GET /sms_code/15850530699?image_code=J9YJ&uuid=1 HTTP/1.1" 301 0
WARNING 2020-04-24 23:20:52,148 log 222 Bad Request: /sms_code/15850530699/
WARNING 2020-04-24 23:20:52,149 basehttp 157 "GET /sms_code/15850530699/?image_code=J9YJ&uuid=1 HTTP/1.1" 400 48
INFO 2020-04-24 23:21:22,064 basehttp 157 "GET /image_codes/1 HTTP/1.1" 301 0
INFO 2020-04-24 23:21:22,129 basehttp 157 "GET /image_codes/1/ HTTP/1.1" 200 3276
INFO 2020-04-24 23:21:34,506 basehttp 157 "GET /sms_code/15850530699?image_code=c5pa&uuid=1 HTTP/1.1" 301 0
WARNING 2020-04-24 23:21:34,552 log 222 Bad Request: /sms_code/15850530699/
WARNING 2020-04-24 23:21:34,554 basehttp 157 "GET /sms_code/15850530699/?image_code=c5pa&uuid=1 HTTP/1.1" 400 48
INFO 2020-04-24 23:22:29,737 basehttp 157 "GET /image_codes/1/ HTTP/1.1" 200 3557
INFO 2020-04-24 23:22:49,031 basehttp 157 "GET /sms_code/15850530699?image_code=OKWP&uuid=1/ HTTP/1.1" 301 0
INFO 2020-04-24 23:22:49,083 basehttp 157 "GET /sms_code/15850530699/?image_code=OKWP&uuid=1/ HTTP/1.1" 200 72
INFO 2020-04-24 23:23:15,754 basehttp 157 "GET /image_codes/1/ HTTP/1.1" 200 3506
WARNING 2020-04-24 23:23:28,528 log 222 Bad Request: /sms_code/15850530699/
WARNING 2020-04-24 23:23:28,529 basehttp 157 "GET /sms_code/15850530699/?image_code=MXCD&uuid=1 HTTP/1.1" 400 48
INFO 2020-04-24 23:25:11,669 basehttp 157 "GET /image_codes/1/ HTTP/1.1" 200 3114
WARNING 2020-04-24 23:25:57,400 log 222 Bad Request: /sms_code/15850530699/
WARNING 2020-04-24 23:25:57,401 basehttp 157 "GET /sms_code/15850530699/?image_code=L7ZR&uuid=1 HTTP/1.1" 400 48
INFO 2020-04-24 23:26:58,442 autoreload 222 /usr/src/app/apps/verifications/views.py changed, reloading.
INFO 2020-04-24 23:26:59,453 autoreload 598 Watching for file changes with StatReloader
INFO 2020-04-24 23:27:04,244 basehttp 157 "GET /image_codes/1/ HTTP/1.1" 200 2880
WARNING 2020-04-24 23:27:17,263 log 222 Bad Request: /sms_code/15850530699/
WARNING 2020-04-24 23:27:17,264 basehttp 157 "GET /sms_code/15850530699/?image_code=S7IR&uuid=1 HTTP/1.1" 400 48
